Workbook

Sheet How to Use
A1: BALLPARK COST ESTIMATOR v2.0
A2: Fast, defensible order-of-magnitude pricing for a multi-feature software project
A4: WHAT THIS TOOL IS FOR
B5: Use this workbook at the proposal stage, when you have a feature list but not signed-off specifications. It converts a 1-5 score across five dimensions into a price band for each feature, then rolls the features up into a project number with the overheads that feature-level scoring always misses.
B6: It is an order-of-magnitude tool. Expect the project total to land within roughly plus or minus 30 to 40 per cent of actual. It is not a quote and should never be presented as one.
B7: When a single feature matters enough to get right, stop using this sheet for that feature and run the companion FEATURE DEEP ESTIMATOR workbook instead. Bring the result back to the Variance sheet in that workbook.
A9: HOW TO FILL IT IN
B10: Step | C10: What you do | D10: Why it matters
B11: 1. List every feature | C11: One row per deliverable feature on the Ballpark Estimator sheet. Split anything you cannot describe in a single sentence.
B12: 2. Score all five dimensions | C12: Enter 1-5 in each yellow cell. Use the Scoring Guide sheet for the anchor descriptions so scores stay consistent between estimators.
B13: 3. Read the flag column | C13: Any row flagged for a deep estimate is telling you the money at stake exceeds what this tool can responsibly price.
B14: 4. Set the project context factors | C14: On the Project Roll-up sheet. These apply to the whole project, not to individual features, and they routinely move the total by 20-50 per cent.
B15: 5. Review the overhead percentages | C15: The defaults are starting points, not truths. Tune them once against your own delivered projects and then leave them alone.
B16: 6. Write the assumptions and exclusions | C16: The bottom of the Project Roll-up sheet. An estimate without these is a liability, not an estimate.
A18: CELL COLOUR LEGEND
B19: Yellow fill, blue text | C19: You edit this. Every input in the workbook is marked this way.
B20: White, black text | C20: Calculated. Do not overwrite - you will break the roll-up.
B21: Green text | C21: Pulled from another sheet in this workbook.
A23: WHAT CHANGED FROM v1 - AND WHY
B24: Issue in v1 | C24: Change in v2
B25: All five dimensions weighted equally | C25: Weighted 20/10/20/30/20. In an agent-assisted workflow raw feature size is the cheapest thing to produce, while unclear requirements are the most expensive. Weights are editable on the estimator sheet.
B26: Every Medium feature priced at the same $2,750 midpoint | C26: Price now interpolates continuously across the whole 5-25 score range, so a 12 and a 17 no longer quote identically.
B27: One score point moved price from $10,000 to $25,000 at the tier edge | C27: Tier price bands are now continuous - each band ends where the next begins - so there is no cliff anywhere on the curve.
B28: Project range was the naive sum of every feature's low and high | C28: Project spread is now combined statistically. All features hitting their low simultaneously is not a real scenario, so the naive sum overstates the range.
B29: Nothing outside feature build was priced | C29: Discovery, design, QA, DevOps, documentation, project management and cross-feature integration are now explicit lines on the roll-up.
B30: No project-wide context | C30: Codebase maturity, stack familiarity, spec quality, compliance and client decision structure now scale the whole project.
B31: Uncertainty was scored but never used | C31: It now drives both the per-feature spread and the project contingency percentage.
B32: No assumptions, exclusions or expiry | C32: All three are now required fields at the bottom of the roll-up.
B33: No way to learn from delivered work | C33: The companion Deep Estimator carries an Actuals and Calibration sheet. Feed those factors back into the parameters here.

Sheet Ballpark Estimator
A1: BALLPARK COST ESTIMATOR
A2: Score each feature 1-5 across five weighted dimensions. Price interpolates continuously - no tier cliffs.
B3: Project | D3: Client | F3: Prepared by | H3: Date | J3: Version | L3: Status | N3: Ballpark only - not a quote
B5: DIMENSION WEIGHTS (edit to re-tune) | C5: 0.2 | D5: 0.1 | E5: 0.2 | F5: 0.3 | G5: 0.2 | H5: =SUM($C$5:$G$5) -> 1 | I5: =IF(ABS($H$5-1)<0.0001,"weights OK","FIX: must total 100%") -> weights OK | J5: Size is deliberately the lightest weight and Uncertainty the heaviest - see How to Use.
A6: SYSTEM / MODULE | B6: FEATURE / WORK ITEM | C6: TECH COMPLEXITY (1-5) | D6: FEATURE SIZE (1-5) | E6: DEPEND- ENCIES (1-5) | F6: UNCER- TAINTY (1-5) | G6: RISK (1-5) | H6: WEIGHTED SCORE (5-25) | I6: TIER | J6: POINT ESTIMATE | K6: +/- SPREAD | L6: EST. LOW | M6: EST. HIGH | N6: FLAG / ACTION
B7: User authentication (email + OAuth) | C7: 1 | D7: 3 | E7: 3 | F7: 3 | G7: 3 | H7: =IF($B7="",0,SUMPRODUCT($C7:$G7,$C$5:$G$5)*5) -> 13 | I7: {=IF(OR($B7="",$H7<5),"",INDEX('Tier Reference'!$B$6:$B$9,MATCH($H7,'Tier Reference'!$C$6:$C$9,1)))} -> M - Medium | J7: {=IF(OR($B7="",$H7<5),0,INDEX('Tier Reference'!$E$6:$E$9,MATCH($H7,'Tier Reference'!$C$6:$C$9,1))+(MIN($H7,25)-INDEX('Tier Reference'!$C$6:$C$9,MATCH($H7,'Tier Reference'!$C$6:$C$9,1)))/(INDEX('Tier Reference'!$D$6:$D$9,MATCH($H7,'Tier Reference'!$C$6:$C$9,1))-INDEX('Tier Reference'!$C$6:$C$9,MATCH($H7,'Tier Reference'!$C$6:$C$9,1)))*(INDEX('Tier Reference'!$F$6:$F$9,MATCH($H7,'Tier Reference'!$C$6:$C$9,1))-INDEX('Tier Reference'!$E$6:$E$9,MATCH($H7,'Tier Reference'!$C$6:$C$9,1))))} -> 2125 | K7: =IF($B7="",0,'Tier Reference'!$C$14+MAX(0,$F7-1)*'Tier Reference'!$C$15+MAX(0,$G7-1)*'Tier Reference'!$C$16) -> 0.35 | L7: =IF($B7="",0,$J7*(1-$K7)) -> 1381.25 | M7: =IF($B7="",0,$J7*(1+$K7)) -> 2868.75 | N7: =IF($B7="","",IF(COUNT($C7:$G7)<5,"Incomplete - score all five",IF(AND($H7>='Tier Reference'!$C$9,$D7=5),"SPLIT into sub-features",IF($H7>='Tier Reference'!$C$9,"Deep estimate required",IF($K7>=0.4,"Deep estimate recommended",IF($J7>='Tier Reference'!$C$17,"Deep estimate recommended",""))))))
B8: Role-based access control | C8: 4 | D8: 4 | E8: 4 | F8: 4 | G8: 4 | H8: =IF($B8="",0,SUMPRODUCT($C8:$G8,$C$5:$G$5)*5) -> 20 | I8: {=IF(OR($B8="",$H8<5),"",INDEX('Tier Reference'!$B$6:$B$9,MATCH($H8,'Tier Reference'!$C$6:$C$9,1)))} -> L - Large | J8: {=IF(OR($B8="",$H8<5),0,INDEX('Tier Reference'!$E$6:$E$9,MATCH($H8,'Tier Reference'!$C$6:$C$9,1))+(MIN($H8,25)-INDEX('Tier Reference'!$C$6:$C$9,MATCH($H8,'Tier Reference'!$C$6:$C$9,1)))/(INDEX('Tier Reference'!$D$6:$D$9,MATCH($H8,'Tier Reference'!$C$6:$C$9,1))-INDEX('Tier Reference'!$C$6:$C$9,MATCH($H8,'Tier Reference'!$C$6:$C$9,1)))*(INDEX('Tier Reference'!$F$6:$F$9,MATCH($H8,'Tier Reference'!$C$6:$C$9,1))-INDEX('Tier Reference'!$E$6:$E$9,MATCH($H8,'Tier Reference'!$C$6:$C$9,1))))} -> 7000 | K8: =IF($B8="",0,'Tier Reference'!$C$14+MAX(0,$F8-1)*'Tier Reference'!$C$15+MAX(0,$G8-1)*'Tier Reference'!$C$16) -> 0.45 | L8: =IF($B8="",0,$J8*(1-$K8)) -> 3850 | M8: =IF($B8="",0,$J8*(1+$K8)) -> 10150 | N8: =IF($B8="","",IF(COUNT($C8:$G8)<5,"Incomplete - score all five",IF(AND($H8>='Tier Reference'!$C$9,$D8=5),"SPLIT into sub-features",IF($H8>='Tier Reference'!$C$9,"Deep estimate required",IF($K8>=0.4,"Deep estimate recommended",IF($J8>='Tier Reference'!$C$17,"Deep estimate recommended","")))))) -> Deep estimate recommended
B9: Stripe billing & subscription | C9: 3 | D9: 3 | E9: 4 | F9: 2 | G9: 4 | H9: =IF($B9="",0,SUMPRODUCT($C9:$G9,$C$5:$G$5)*5) -> 15.5 | I9: {=IF(OR($B9="",$H9<5),"",INDEX('Tier Reference'!$B$6:$B$9,MATCH($H9,'Tier Reference'!$C$6:$C$9,1)))} -> M - Medium | J9: {=IF(OR($B9="",$H9<5),0,INDEX('Tier Reference'!$E$6:$E$9,MATCH($H9,'Tier Reference'!$C$6:$C$9,1))+(MIN($H9,25)-INDEX('Tier Reference'!$C$6:$C$9,MATCH($H9,'Tier Reference'!$C$6:$C$9,1)))/(INDEX('Tier Reference'!$D$6:$D$9,MATCH($H9,'Tier Reference'!$C$6:$C$9,1))-INDEX('Tier Reference'!$C$6:$C$9,MATCH($H9,'Tier Reference'!$C$6:$C$9,1)))*(INDEX('Tier Reference'!$F$6:$F$9,MATCH($H9,'Tier Reference'!$C$6:$C$9,1))-INDEX('Tier Reference'!$E$6:$E$9,MATCH($H9,'Tier Reference'!$C$6:$C$9,1))))} -> 3166.6667 | K9: =IF($B9="",0,'Tier Reference'!$C$14+MAX(0,$F9-1)*'Tier Reference'!$C$15+MAX(0,$G9-1)*'Tier Reference'!$C$16) -> 0.31 | L9: =IF($B9="",0,$J9*(1-$K9)) -> 2185 | M9: =IF($B9="",0,$J9*(1+$K9)) -> 4148.3333 | N9: =IF($B9="","",IF(COUNT($C9:$G9)<5,"Incomplete - score all five",IF(AND($H9>='Tier Reference'!$C$9,$D9=5),"SPLIT into sub-features",IF($H9>='Tier Reference'!$C$9,"Deep estimate required",IF($K9>=0.4,"Deep estimate recommended",IF($J9>='Tier Reference'!$C$17,"Deep estimate recommended",""))))))
B10: Admin dashboard (CRUD + search) | C10: 2 | D10: 3 | E10: 2 | F10: 1 | G10: 1 | H10: =IF($B10="",0,SUMPRODUCT($C10:$G10,$C$5:$G$5)*5) -> 8 | I10: {=IF(OR($B10="",$H10<5),"",INDEX('Tier Reference'!$B$6:$B$9,MATCH($H10,'Tier Reference'!$C$6:$C$9,1)))} -> S - Simple | J10: {=IF(OR($B10="",$H10<5),0,INDEX('Tier Reference'!$E$6:$E$9,MATCH($H10,'Tier Reference'!$C$6:$C$9,1))+(MIN($H10,25)-INDEX('Tier Reference'!$C$6:$C$9,MATCH($H10,'Tier Reference'!$C$6:$C$9,1)))/(INDEX('Tier Reference'!$D$6:$D$9,MATCH($H10,'Tier Reference'!$C$6:$C$9,1))-INDEX('Tier Reference'!$C$6:$C$9,MATCH($H10,'Tier Reference'!$C$6:$C$9,1)))*(INDEX('Tier Reference'!$F$6:$F$9,MATCH($H10,'Tier Reference'!$C$6:$C$9,1))-INDEX('Tier Reference'!$E$6:$E$9,MATCH($H10,'Tier Reference'!$C$6:$C$9,1))))} -> 961.53846 | K10: =IF($B10="",0,'Tier Reference'!$C$14+MAX(0,$F10-1)*'Tier Reference'!$C$15+MAX(0,$G10-1)*'Tier Reference'!$C$16) -> 0.15 | L10: =IF($B10="",0,$J10*(1-$K10)) -> 817.30769 | M10: =IF($B10="",0,$J10*(1+$K10)) -> 1105.7692 | N10: =IF($B10="","",IF(COUNT($C10:$G10)<5,"Incomplete - score all five",IF(AND($H10>='Tier Reference'!$C$9,$D10=5),"SPLIT into sub-features",IF($H10>='Tier Reference'!$C$9,"Deep estimate required",IF($K10>=0.4,"Deep estimate recommended",IF($J10>='Tier Reference'!$C$17,"Deep estimate recommended",""))))))
B11: AI chat with streaming + history | C11: 4 | D11: 3 | E11: 3 | F11: 3 | G11: 2 | H11: =IF($B11="",0,SUMPRODUCT($C11:$G11,$C$5:$G$5)*5) -> 15 | I11: {=IF(OR($B11="",$H11<5),"",INDEX('Tier Reference'!$B$6:$B$9,MATCH($H11,'Tier Reference'!$C$6:$C$9,1)))} -> M - Medium | J11: {=IF(OR($B11="",$H11<5),0,INDEX('Tier Reference'!$E$6:$E$9,MATCH($H11,'Tier Reference'!$C$6:$C$9,1))+(MIN($H11,25)-INDEX('Tier Reference'!$C$6:$C$9,MATCH($H11,'Tier Reference'!$C$6:$C$9,1)))/(INDEX('Tier Reference'!$D$6:$D$9,MATCH($H11,'Tier Reference'!$C$6:$C$9,1))-INDEX('Tier Reference'!$C$6:$C$9,MATCH($H11,'Tier Reference'!$C$6:$C$9,1)))*(INDEX('Tier Reference'!$F$6:$F$9,MATCH($H11,'Tier Reference'!$C$6:$C$9,1))-INDEX('Tier Reference'!$E$6:$E$9,MATCH($H11,'Tier Reference'!$C$6:$C$9,1))))} -> 2958.3333 | K11: =IF($B11="",0,'Tier Reference'!$C$14+MAX(0,$F11-1)*'Tier Reference'!$C$15+MAX(0,$G11-1)*'Tier Reference'!$C$16) -> 0.32 | L11: =IF($B11="",0,$J11*(1-$K11)) -> 2011.6667 | M11: =IF($B11="",0,$J11*(1+$K11)) -> 3905 | N11: =IF($B11="","",IF(COUNT($C11:$G11)<5,"Incomplete - score all five",IF(AND($H11>='Tier Reference'!$C$9,$D11=5),"SPLIT into sub-features",IF($H11>='Tier Reference'!$C$9,"Deep estimate required",IF($K11>=0.4,"Deep estimate recommended",IF($J11>='Tier Reference'!$C$17,"Deep estimate recommended",""))))))
H12: =IF($B12="",0,SUMPRODUCT($C12:$G12,$C$5:$G$5)*5) -> 0 | I12: {=IF(OR($B12="",$H12<5),"",INDEX('Tier Reference'!$B$6:$B$9,MATCH($H12,'Tier Reference'!$C$6:$C$9,1)))} | J12: {=IF(OR($B12="",$H12<5),0,INDEX('Tier Reference'!$E$6:$E$9,MATCH($H12,'Tier Reference'!$C$6:$C$9,1))+(MIN($H12,25)-INDEX('Tier Reference'!$C$6:$C$9,MATCH($H12,'Tier Reference'!$C$6:$C$9,1)))/(INDEX('Tier Reference'!$D$6:$D$9,MATCH($H12,'Tier Reference'!$C$6:$C$9,1))-INDEX('Tier Reference'!$C$6:$C$9,MATCH($H12,'Tier Reference'!$C$6:$C$9,1)))*(INDEX('Tier Reference'!$F$6:$F$9,MATCH($H12,'Tier Reference'!$C$6:$C$9,1))-INDEX('Tier Reference'!$E$6:$E$9,MATCH($H12,'Tier Reference'!$C$6:$C$9,1))))} -> 0 | K12: =IF($B12="",0,'Tier Reference'!$C$14+MAX(0,$F12-1)*'Tier Reference'!$C$15+MAX(0,$G12-1)*'Tier Reference'!$C$16) -> 0 | L12: =IF($B12="",0,$J12*(1-$K12)) -> 0 | M12: =IF($B12="",0,$J12*(1+$K12)) -> 0 | N12: =IF($B12="","",IF(COUNT($C12:$G12)<5,"Incomplete - score all five",IF(AND($H12>='Tier Reference'!$C$9,$D12=5),"SPLIT into sub-features",IF($H12>='Tier Reference'!$C$9,"Deep estimate required",IF($K12>=0.4,"Deep estimate recommended",IF($J12>='Tier Reference'!$C$17,"Deep estimate recommended",""))))))
H13: =IF($B13="",0,SUMPRODUCT($C13:$G13,$C$5:$G$5)*5) -> 0 | I13: {=IF(OR($B13="",$H13<5),"",INDEX('Tier Reference'!$B$6:$B$9,MATCH($H13,'Tier Reference'!$C$6:$C$9,1)))} | J13: {=IF(OR($B13="",$H13<5),0,INDEX('Tier Reference'!$E$6:$E$9,MATCH($H13,'Tier Reference'!$C$6:$C$9,1))+(MIN($H13,25)-INDEX('Tier Reference'!$C$6:$C$9,MATCH($H13,'Tier Reference'!$C$6:$C$9,1)))/(INDEX('Tier Reference'!$D$6:$D$9,MATCH($H13,'Tier Reference'!$C$6:$C$9,1))-INDEX('Tier Reference'!$C$6:$C$9,MATCH($H13,'Tier Reference'!$C$6:$C$9,1)))*(INDEX('Tier Reference'!$F$6:$F$9,MATCH($H13,'Tier Reference'!$C$6:$C$9,1))-INDEX('Tier Reference'!$E$6:$E$9,MATCH($H13,'Tier Reference'!$C$6:$C$9,1))))} -> 0 | K13: =IF($B13="",0,'Tier Reference'!$C$14+MAX(0,$F13-1)*'Tier Reference'!$C$15+MAX(0,$G13-1)*'Tier Reference'!$C$16) -> 0 | L13: =IF($B13="",0,$J13*(1-$K13)) -> 0 | M13: =IF($B13="",0,$J13*(1+$K13)) -> 0 | N13: =IF($B13="","",IF(COUNT($C13:$G13)<5,"Incomplete - score all five",IF(AND($H13>='Tier Reference'!$C$9,$D13=5),"SPLIT into sub-features",IF($H13>='Tier Reference'!$C$9,"Deep estimate required",IF($K13>=0.4,"Deep estimate recommended",IF($J13>='Tier Reference'!$C$17,"Deep estimate recommended",""))))))
H14: =IF($B14="",0,SUMPRODUCT($C14:$G14,$C$5:$G$5)*5) -> 0 | I14: {=IF(OR($B14="",$H14<5),"",INDEX('Tier Reference'!$B$6:$B$9,MATCH($H14,'Tier Reference'!$C$6:$C$9,1)))} | J14: {=IF(OR($B14="",$H14<5),0,INDEX('Tier Reference'!$E$6:$E$9,MATCH($H14,'Tier Reference'!$C$6:$C$9,1))+(MIN($H14,25)-INDEX('Tier Reference'!$C$6:$C$9,MATCH($H14,'Tier Reference'!$C$6:$C$9,1)))/(INDEX('Tier Reference'!$D$6:$D$9,MATCH($H14,'Tier Reference'!$C$6:$C$9,1))-INDEX('Tier Reference'!$C$6:$C$9,MATCH($H14,'Tier Reference'!$C$6:$C$9,1)))*(INDEX('Tier Reference'!$F$6:$F$9,MATCH($H14,'Tier Reference'!$C$6:$C$9,1))-INDEX('Tier Reference'!$E$6:$E$9,MATCH($H14,'Tier Reference'!$C$6:$C$9,1))))} -> 0 | K14: =IF($B14="",0,'Tier Reference'!$C$14+MAX(0,$F14-1)*'Tier Reference'!$C$15+MAX(0,$G14-1)*'Tier Reference'!$C$16) -> 0 | L14: =IF($B14="",0,$J14*(1-$K14)) -> 0 | M14: =IF($B14="",0,$J14*(1+$K14)) -> 0 | N14: =IF($B14="","",IF(COUNT($C14:$G14)<5,"Incomplete - score all five",IF(AND($H14>='Tier Reference'!$C$9,$D14=5),"SPLIT into sub-features",IF($H14>='Tier Reference'!$C$9,"Deep estimate required",IF($K14>=0.4,"Deep estimate recommended",IF($J14>='Tier Reference'!$C$17,"Deep estimate recommended",""))))))
H15: =IF($B15="",0,SUMPRODUCT($C15:$G15,$C$5:$G$5)*5) -> 0 | I15: {=IF(OR($B15="",$H15<5),"",INDEX('Tier Reference'!$B$6:$B$9,MATCH($H15,'Tier Reference'!$C$6:$C$9,1)))} | J15: {=IF(OR($B15="",$H15<5),0,INDEX('Tier Reference'!$E$6:$E$9,MATCH($H15,'Tier Reference'!$C$6:$C$9,1))+(MIN($H15,25)-INDEX('Tier Reference'!$C$6:$C$9,MATCH($H15,'Tier Reference'!$C$6:$C$9,1)))/(INDEX('Tier Reference'!$D$6:$D$9,MATCH($H15,'Tier Reference'!$C$6:$C$9,1))-INDEX('Tier Reference'!$C$6:$C$9,MATCH($H15,'Tier Reference'!$C$6:$C$9,1)))*(INDEX('Tier Reference'!$F$6:$F$9,MATCH($H15,'Tier Reference'!$C$6:$C$9,1))-INDEX('Tier Reference'!$E$6:$E$9,MATCH($H15,'Tier Reference'!$C$6:$C$9,1))))} -> 0 | K15: =IF($B15="",0,'Tier Reference'!$C$14+MAX(0,$F15-1)*'Tier Reference'!$C$15+MAX(0,$G15-1)*'Tier Reference'!$C$16) -> 0 | L15: =IF($B15="",0,$J15*(1-$K15)) -> 0 | M15: =IF($B15="",0,$J15*(1+$K15)) -> 0 | N15: =IF($B15="","",IF(COUNT($C15:$G15)<5,"Incomplete - score all five",IF(AND($H15>='Tier Reference'!$C$9,$D15=5),"SPLIT into sub-features",IF($H15>='Tier Reference'!$C$9,"Deep estimate required",IF($K15>=0.4,"Deep estimate recommended",IF($J15>='Tier Reference'!$C$17,"Deep estimate recommended",""))))))
H16: =IF($B16="",0,SUMPRODUCT($C16:$G16,$C$5:$G$5)*5) -> 0 | I16: {=IF(OR($B16="",$H16<5),"",INDEX('Tier Reference'!$B$6:$B$9,MATCH($H16,'Tier Reference'!$C$6:$C$9,1)))} | J16: {=IF(OR($B16="",$H16<5),0,INDEX('Tier Reference'!$E$6:$E$9,MATCH($H16,'Tier Reference'!$C$6:$C$9,1))+(MIN($H16,25)-INDEX('Tier Reference'!$C$6:$C$9,MATCH($H16,'Tier Reference'!$C$6:$C$9,1)))/(INDEX('Tier Reference'!$D$6:$D$9,MATCH($H16,'Tier Reference'!$C$6:$C$9,1))-INDEX('Tier Reference'!$C$6:$C$9,MATCH($H16,'Tier Reference'!$C$6:$C$9,1)))*(INDEX('Tier Reference'!$F$6:$F$9,MATCH($H16,'Tier Reference'!$C$6:$C$9,1))-INDEX('Tier Reference'!$E$6:$E$9,MATCH($H16,'Tier Reference'!$C$6:$C$9,1))))} -> 0 | K16: =IF($B16="",0,'Tier Reference'!$C$14+MAX(0,$F16-1)*'Tier Reference'!$C$15+MAX(0,$G16-1)*'Tier Reference'!$C$16) -> 0 | L16: =IF($B16="",0,$J16*(1-$K16)) -> 0 | M16: =IF($B16="",0,$J16*(1+$K16)) -> 0 | N16: =IF($B16="","",IF(COUNT($C16:$G16)<5,"Incomplete - score all five",IF(AND($H16>='Tier Reference'!$C$9,$D16=5),"SPLIT into sub-features",IF($H16>='Tier Reference'!$C$9,"Deep estimate required",IF($K16>=0.4,"Deep estimate recommended",IF($J16>='Tier Reference'!$C$17,"Deep estimate recommended",""))))))
H17: =IF($B17="",0,SUMPRODUCT($C17:$G17,$C$5:$G$5)*5) -> 0 | I17: {=IF(OR($B17="",$H17<5),"",INDEX('Tier Reference'!$B$6:$B$9,MATCH($H17,'Tier Reference'!$C$6:$C$9,1)))} | J17: {=IF(OR($B17="",$H17<5),0,INDEX('Tier Reference'!$E$6:$E$9,MATCH($H17,'Tier Reference'!$C$6:$C$9,1))+(MIN($H17,25)-INDEX('Tier Reference'!$C$6:$C$9,MATCH($H17,'Tier Reference'!$C$6:$C$9,1)))/(INDEX('Tier Reference'!$D$6:$D$9,MATCH($H17,'Tier Reference'!$C$6:$C$9,1))-INDEX('Tier Reference'!$C$6:$C$9,MATCH($H17,'Tier Reference'!$C$6:$C$9,1)))*(INDEX('Tier Reference'!$F$6:$F$9,MATCH($H17,'Tier Reference'!$C$6:$C$9,1))-INDEX('Tier Reference'!$E$6:$E$9,MATCH($H17,'Tier Reference'!$C$6:$C$9,1))))} -> 0 | K17: =IF($B17="",0,'Tier Reference'!$C$14+MAX(0,$F17-1)*'Tier Reference'!$C$15+MAX(0,$G17-1)*'Tier Reference'!$C$16) -> 0 | L17: =IF($B17="",0,$J17*(1-$K17)) -> 0 | M17: =IF($B17="",0,$J17*(1+$K17)) -> 0 | N17: =IF($B17="","",IF(COUNT($C17:$G17)<5,"Incomplete - score all five",IF(AND($H17>='Tier Reference'!$C$9,$D17=5),"SPLIT into sub-features",IF($H17>='Tier Reference'!$C$9,"Deep estimate required",IF($K17>=0.4,"Deep estimate recommended",IF($J17>='Tier Reference'!$C$17,"Deep estimate recommended",""))))))
H18: =IF($B18="",0,SUMPRODUCT($C18:$G18,$C$5:$G$5)*5) -> 0 | I18: {=IF(OR($B18="",$H18<5),"",INDEX('Tier Reference'!$B$6:$B$9,MATCH($H18,'Tier Reference'!$C$6:$C$9,1)))} | J18: {=IF(OR($B18="",$H18<5),0,INDEX('Tier Reference'!$E$6:$E$9,MATCH($H18,'Tier Reference'!$C$6:$C$9,1))+(MIN($H18,25)-INDEX('Tier Reference'!$C$6:$C$9,MATCH($H18,'Tier Reference'!$C$6:$C$9,1)))/(INDEX('Tier Reference'!$D$6:$D$9,MATCH($H18,'Tier Reference'!$C$6:$C$9,1))-INDEX('Tier Reference'!$C$6:$C$9,MATCH($H18,'Tier Reference'!$C$6:$C$9,1)))*(INDEX('Tier Reference'!$F$6:$F$9,MATCH($H18,'Tier Reference'!$C$6:$C$9,1))-INDEX('Tier Reference'!$E$6:$E$9,MATCH($H18,'Tier Reference'!$C$6:$C$9,1))))} -> 0 | K18: =IF($B18="",0,'Tier Reference'!$C$14+MAX(0,$F18-1)*'Tier Reference'!$C$15+MAX(0,$G18-1)*'Tier Reference'!$C$16) -> 0 | L18: =IF($B18="",0,$J18*(1-$K18)) -> 0 | M18: =IF($B18="",0,$J18*(1+$K18)) -> 0 | N18: =IF($B18="","",IF(COUNT($C18:$G18)<5,"Incomplete - score all five",IF(AND($H18>='Tier Reference'!$C$9,$D18=5),"SPLIT into sub-features",IF($H18>='Tier Reference'!$C$9,"Deep estimate required",IF($K18>=0.4,"Deep estimate recommended",IF($J18>='Tier Reference'!$C$17,"Deep estimate recommended",""))))))
H19: =IF($B19="",0,SUMPRODUCT($C19:$G19,$C$5:$G$5)*5) -> 0 | I19: {=IF(OR($B19="",$H19<5),"",INDEX('Tier Reference'!$B$6:$B$9,MATCH($H19,'Tier Reference'!$C$6:$C$9,1)))} | J19: {=IF(OR($B19="",$H19<5),0,INDEX('Tier Reference'!$E$6:$E$9,MATCH($H19,'Tier Reference'!$C$6:$C$9,1))+(MIN($H19,25)-INDEX('Tier Reference'!$C$6:$C$9,MATCH($H19,'Tier Reference'!$C$6:$C$9,1)))/(INDEX('Tier Reference'!$D$6:$D$9,MATCH($H19,'Tier Reference'!$C$6:$C$9,1))-INDEX('Tier Reference'!$C$6:$C$9,MATCH($H19,'Tier Reference'!$C$6:$C$9,1)))*(INDEX('Tier Reference'!$F$6:$F$9,MATCH($H19,'Tier Reference'!$C$6:$C$9,1))-INDEX('Tier Reference'!$E$6:$E$9,MATCH($H19,'Tier Reference'!$C$6:$C$9,1))))} -> 0 | K19: =IF($B19="",0,'Tier Reference'!$C$14+MAX(0,$F19-1)*'Tier Reference'!$C$15+MAX(0,$G19-1)*'Tier Reference'!$C$16) -> 0 | L19: =IF($B19="",0,$J19*(1-$K19)) -> 0 | M19: =IF($B19="",0,$J19*(1+$K19)) -> 0 | N19: =IF($B19="","",IF(COUNT($C19:$G19)<5,"Incomplete - score all five",IF(AND($H19>='Tier Reference'!$C$9,$D19=5),"SPLIT into sub-features",IF($H19>='Tier Reference'!$C$9,"Deep estimate required",IF($K19>=0.4,"Deep estimate recommended",IF($J19>='Tier Reference'!$C$17,"Deep estimate recommended",""))))))
H20: =IF($B20="",0,SUMPRODUCT($C20:$G20,$C$5:$G$5)*5) -> 0 | I20: {=IF(OR($B20="",$H20<5),"",INDEX('Tier Reference'!$B$6:$B$9,MATCH($H20,'Tier Reference'!$C$6:$C$9,1)))} | J20: {=IF(OR($B20="",$H20<5),0,INDEX('Tier Reference'!$E$6:$E$9,MATCH($H20,'Tier Reference'!$C$6:$C$9,1))+(MIN($H20,25)-INDEX('Tier Reference'!$C$6:$C$9,MATCH($H20,'Tier Reference'!$C$6:$C$9,1)))/(INDEX('Tier Reference'!$D$6:$D$9,MATCH($H20,'Tier Reference'!$C$6:$C$9,1))-INDEX('Tier Reference'!$C$6:$C$9,MATCH($H20,'Tier Reference'!$C$6:$C$9,1)))*(INDEX('Tier Reference'!$F$6:$F$9,MATCH($H20,'Tier Reference'!$C$6:$C$9,1))-INDEX('Tier Reference'!$E$6:$E$9,MATCH($H20,'Tier Reference'!$C$6:$C$9,1))))} -> 0 | K20: =IF($B20="",0,'Tier Reference'!$C$14+MAX(0,$F20-1)*'Tier Reference'!$C$15+MAX(0,$G20-1)*'Tier Reference'!$C$16) -> 0 | L20: =IF($B20="",0,$J20*(1-$K20)) -> 0 | M20: =IF($B20="",0,$J20*(1+$K20)) -> 0 | N20: =IF($B20="","",IF(COUNT($C20:$G20)<5,"Incomplete - score all five",IF(AND($H20>='Tier Reference'!$C$9,$D20=5),"SPLIT into sub-features",IF($H20>='Tier Reference'!$C$9,"Deep estimate required",IF($K20>=0.4,"Deep estimate recommended",IF($J20>='Tier Reference'!$C$17,"Deep estimate recommended",""))))))
H21: =IF($B21="",0,SUMPRODUCT($C21:$G21,$C$5:$G$5)*5) -> 0 | I21: {=IF(OR($B21="",$H21<5),"",INDEX('Tier Reference'!$B$6:$B$9,MATCH($H21,'Tier Reference'!$C$6:$C$9,1)))} | J21: {=IF(OR($B21="",$H21<5),0,INDEX('Tier Reference'!$E$6:$E$9,MATCH($H21,'Tier Reference'!$C$6:$C$9,1))+(MIN($H21,25)-INDEX('Tier Reference'!$C$6:$C$9,MATCH($H21,'Tier Reference'!$C$6:$C$9,1)))/(INDEX('Tier Reference'!$D$6:$D$9,MATCH($H21,'Tier Reference'!$C$6:$C$9,1))-INDEX('Tier Reference'!$C$6:$C$9,MATCH($H21,'Tier Reference'!$C$6:$C$9,1)))*(INDEX('Tier Reference'!$F$6:$F$9,MATCH($H21,'Tier Reference'!$C$6:$C$9,1))-INDEX('Tier Reference'!$E$6:$E$9,MATCH($H21,'Tier Reference'!$C$6:$C$9,1))))} -> 0 | K21: =IF($B21="",0,'Tier Reference'!$C$14+MAX(0,$F21-1)*'Tier Reference'!$C$15+MAX(0,$G21-1)*'Tier Reference'!$C$16) -> 0 | L21: =IF($B21="",0,$J21*(1-$K21)) -> 0 | M21: =IF($B21="",0,$J21*(1+$K21)) -> 0 | N21: =IF($B21="","",IF(COUNT($C21:$G21)<5,"Incomplete - score all five",IF(AND($H21>='Tier Reference'!$C$9,$D21=5),"SPLIT into sub-features",IF($H21>='Tier Reference'!$C$9,"Deep estimate required",IF($K21>=0.4,"Deep estimate recommended",IF($J21>='Tier Reference'!$C$17,"Deep estimate recommended",""))))))
H22: =IF($B22="",0,SUMPRODUCT($C22:$G22,$C$5:$G$5)*5) -> 0 | I22: {=IF(OR($B22="",$H22<5),"",INDEX('Tier Reference'!$B$6:$B$9,MATCH($H22,'Tier Reference'!$C$6:$C$9,1)))} | J22: {=IF(OR($B22="",$H22<5),0,INDEX('Tier Reference'!$E$6:$E$9,MATCH($H22,'Tier Reference'!$C$6:$C$9,1))+(MIN($H22,25)-INDEX('Tier Reference'!$C$6:$C$9,MATCH($H22,'Tier Reference'!$C$6:$C$9,1)))/(INDEX('Tier Reference'!$D$6:$D$9,MATCH($H22,'Tier Reference'!$C$6:$C$9,1))-INDEX('Tier Reference'!$C$6:$C$9,MATCH($H22,'Tier Reference'!$C$6:$C$9,1)))*(INDEX('Tier Reference'!$F$6:$F$9,MATCH($H22,'Tier Reference'!$C$6:$C$9,1))-INDEX('Tier Reference'!$E$6:$E$9,MATCH($H22,'Tier Reference'!$C$6:$C$9,1))))} -> 0 | K22: =IF($B22="",0,'Tier Reference'!$C$14+MAX(0,$F22-1)*'Tier Reference'!$C$15+MAX(0,$G22-1)*'Tier Reference'!$C$16) -> 0 | L22: =IF($B22="",0,$J22*(1-$K22)) -> 0 | M22: =IF($B22="",0,$J22*(1+$K22)) -> 0 | N22: =IF($B22="","",IF(COUNT($C22:$G22)<5,"Incomplete - score all five",IF(AND($H22>='Tier Reference'!$C$9,$D22=5),"SPLIT into sub-features",IF($H22>='Tier Reference'!$C$9,"Deep estimate required",IF($K22>=0.4,"Deep estimate recommended",IF($J22>='Tier Reference'!$C$17,"Deep estimate recommended",""))))))
H23: =IF($B23="",0,SUMPRODUCT($C23:$G23,$C$5:$G$5)*5) -> 0 | I23: {=IF(OR($B23="",$H23<5),"",INDEX('Tier Reference'!$B$6:$B$9,MATCH($H23,'Tier Reference'!$C$6:$C$9,1)))} | J23: {=IF(OR($B23="",$H23<5),0,INDEX('Tier Reference'!$E$6:$E$9,MATCH($H23,'Tier Reference'!$C$6:$C$9,1))+(MIN($H23,25)-INDEX('Tier Reference'!$C$6:$C$9,MATCH($H23,'Tier Reference'!$C$6:$C$9,1)))/(INDEX('Tier Reference'!$D$6:$D$9,MATCH($H23,'Tier Reference'!$C$6:$C$9,1))-INDEX('Tier Reference'!$C$6:$C$9,MATCH($H23,'Tier Reference'!$C$6:$C$9,1)))*(INDEX('Tier Reference'!$F$6:$F$9,MATCH($H23,'Tier Reference'!$C$6:$C$9,1))-INDEX('Tier Reference'!$E$6:$E$9,MATCH($H23,'Tier Reference'!$C$6:$C$9,1))))} -> 0 | K23: =IF($B23="",0,'Tier Reference'!$C$14+MAX(0,$F23-1)*'Tier Reference'!$C$15+MAX(0,$G23-1)*'Tier Reference'!$C$16) -> 0 | L23: =IF($B23="",0,$J23*(1-$K23)) -> 0 | M23: =IF($B23="",0,$J23*(1+$K23)) -> 0 | N23: =IF($B23="","",IF(COUNT($C23:$G23)<5,"Incomplete - score all five",IF(AND($H23>='Tier Reference'!$C$9,$D23=5),"SPLIT into sub-features",IF($H23>='Tier Reference'!$C$9,"Deep estimate required",IF($K23>=0.4,"Deep estimate recommended",IF($J23>='Tier Reference'!$C$17,"Deep estimate recommended",""))))))
... H36: =IF($B36="",0,SUMPRODUCT($C36:$G36,$C$5:$G$5)*5) -> 0 | I36: {=IF(OR($B36="",$H36<5),"",INDEX('Tier Reference'!$B$6:$B$9,MATCH($H36,'Tier Reference'!$C$6:$C$9,1)))} | J36: {=IF(OR($B36="",$H36<5),0,INDEX('Tier Reference'!$E$6:$E$9,MATCH($H36,'Tier Reference'!$C$6:$C$9,1))+(MIN($H36,25)-INDEX('Tier Reference'!$C$6:$C$9,MATCH($H36,'Tier Reference'!$C$6:$C$9,1)))/(INDEX('Tier Reference'!$D$6:$D$9,MATCH($H36,'Tier Reference'!$C$6:$C$9,1))-INDEX('Tier Reference'!$C$6:$C$9,MATCH($H36,'Tier Reference'!$C$6:$C$9,1)))*(INDEX('Tier Reference'!$F$6:$F$9,MATCH($H36,'Tier Reference'!$C$6:$C$9,1))-INDEX('Tier Reference'!$E$6:$E$9,MATCH($H36,'Tier Reference'!$C$6:$C$9,1))))} -> 0 | K36: =IF($B36="",0,'Tier Reference'!$C$14+MAX(0,$F36-1)*'Tier Reference'!$C$15+MAX(0,$G36-1)*'Tier Reference'!$C$16) -> 0 | L36: =IF($B36="",0,$J36*(1-$K36)) -> 0 | M36: =IF($B36="",0,$J36*(1+$K36)) -> 0 | N36: =IF($B36="","",IF(COUNT($C36:$G36)<5,"Incomplete - score all five",IF(AND($H36>='Tier Reference'!$C$9,$D36=5),"SPLIT into sub-features",IF($H36>='Tier Reference'!$C$9,"Deep estimate required",IF($K36>=0.4,"Deep estimate recommended",IF($J36>='Tier Reference'!$C$17,"Deep estimate recommended",""))))))
B37: FEATURE SUBTOTAL | G37: Features: | H37: =COUNTIF($B$7:$B$36,"?*") -> 5 | J37: =SUM($J$7:$J$36) -> 16211.538 | L37: =SUM($L$7:$L$36) -> 10245.224 | M37: =SUM($M$7:$M$36) -> 22177.853 | N37: Build effort only
A39: The Est. Low and Est. High columns above are summed naively and will overstate the true project spread. Use the statistically combined range on the Project Roll-up sheet when you talk to a client. This subtotal covers feature build effort only - it excludes discovery, design, QA, DevOps, documentation, project management, cross-feature integration and contingency. All of those are added on the Project Roll-up sheet.

Sheet Scoring Guide
A1: SCORING GUIDE - COMPLEXITY DIMENSIONS
A2: Anchor descriptions. Two people should score independently and reconcile - it removes most anchoring bias.
A4: TECHNICAL COMPLEXITY
A5: Weight 20%
B6: Score 1 | C6: Score 2 | D6: Score 3 | E6: Score 4 | F6: Score 5
A7: Technical Complexity | B7: Standard CRUD, well-documented library usage, established patterns | C7: Minor customisation of standard patterns, simple state management | D7: Custom business logic, moderate algorithmic complexity, multiple states | E7: Non-trivial algorithms, real-time systems, ML inference, complex data transforms | F7: Novel architecture, distributed systems, low-level optimisation, R&D territory
A9: FEATURE SIZE
A10: Weight 10% - lowest, deliberately. Volume of code is the cheapest thing an agent produces.
B11: Score 1 | C11: Score 2 | D11: Score 3 | E11: Score 4 | F11: Score 5
A12: Feature Size | B12: Single UI element or micro-function, one screen, no persistence | C12: Small self-contained feature, simple form or display component | D12: Medium feature with multiple components and backend logic | E12: Large feature spanning frontend, backend, database and tests | F12: Epic-scale feature with multiple sub-features or screens - split it before scoring
A14: DEPENDENCIES
A15: Weight 20%
B16: Score 1 | C16: Score 2 | D16: Score 3 | E16: Score 4 | F16: Score 5
A17: Dependencies | B17: Fully standalone, no external services or shared state | C17: One internal dependency, for example an auth check | D17: Two or three internal services, or one third-party API | E17: Multiple third-party APIs, or tightly coupled internal systems | F17: Deep cross-system dependencies, legacy integrations, shared infrastructure changes
A19: UNCERTAINTY
A20: Weight 30% - highest. Unclear requirements are the single largest cost driver in agent-assisted delivery.
B21: Score 1 | C21: Score 2 | D21: Score 3 | E21: Score 4 | F21: Score 5
A22: Uncertainty | B22: Fully defined spec, written acceptance criteria, precedent exists in the codebase | C22: Minor ambiguities, resolvable with one clarifying question | D22: Some open questions, design decisions to be made during the build | E22: Significant unknowns, exploratory work needed, spec likely to change | F22: Highly experimental, no clear solution path, outcomes unclear
A24: RISK
A25: Weight 20% - blast radius if it goes wrong, not likelihood.
B26: Score 1 | C26: Score 2 | D26: Score 3 | E26: Score 4 | F26: Score 5
A27: Risk | B27: Fully reversible, no user data, isolated module | C27: Low stakes, easy rollback, minimal user impact | D27: Moderate impact if broken, requires testing, affects multiple users | E27: Payments, auth, data migrations or PII - high business impact | F27: Core infrastructure, compliance requirements, irreversible operations
A29: SCORING DISCIPLINE - THE RULES THAT MAKE SCORES COMPARABLE
A30: - Whole numbers only. If you want to score 3.5, you have not decided which anchor applies - reread both and pick one.
A31: - Score the feature as it will actually be built in THIS codebase, not the textbook version of it.
A32: - Uncertainty is about what you do not know. Risk is about what happens if you get it wrong. A feature can be certain and still high-risk, like a well-understood payment migration.
A33: - Score Uncertainty honestly at the moment of estimating. Scoring it low because you intend to clarify later is how estimates fail.
A34: - If two estimators differ by two or more points on any dimension, the feature is not understood well enough to price. Talk it through before entering a number.
A35: - Never score a feature you cannot describe in one sentence. Split it first.
A36: - Re-score, do not adjust the price. If the number looks wrong, the scores are wrong - fix those.

Sheet Tier Reference
A1: TIER REFERENCE & MODEL PARAMETERS
A2: Price bands are continuous - each band ends exactly where the next begins, so there is no cliff at a tier edge.
B5: TIER | C5: BAND START | D5: BAND END | E5: PRICE LOW | F5: PRICE HIGH | G5: TYPICAL EXAMPLES
B6: S - Simple | C6: 5 | D6: 11.5 | E6: 500 | F6: 1500 | G6: Landing page component, simple form, read-only view, email notification
B7: M - Medium | C7: 11.5 | D7: 17.5 | E7: 1500 | F7: 4000 | G7: User auth, REST API endpoint set, filtered list views, basic admin panel
B8: L - Large | C8: 17.5 | D8: 22.5 | E8: 4000 | F8: 10000 | G8: Payment integration, role-based permissions, real-time updates, data pipeline
B9: XL - Complex | C9: 22.5 | D9: 25 | E9: 10000 | F9: 25000 | G9: AI/ML features, distributed job processing, multi-tenant architecture, compliance modules
B11: Band Start / Band End are score thresholds. Price Low of each tier equals Price High of the tier below, which is what makes the pricing curve continuous. If you change any figure, keep that chain intact or you reintroduce the cliff v1 had.
A13: MODEL PARAMETERS
B14: Base spread when all dimensions score 1 | C14: 0.15 | D14: Minimum honest uncertainty on any estimate. Nothing is ever plus or minus zero.
B15: Extra spread per Uncertainty point above 1 | C15: 0.07 | D15: Uncertainty widens the range faster than anything else.
B16: Extra spread per Risk point above 1 | C16: 0.03 | D16: Risk widens the range too, but less - risk raises cost more than it raises variance.
B17: Point estimate above which a deep estimate is advised | C17: 6000 | D17: Any single feature worth more than this should be estimated bottom-up, not scored.
A19: READ THIS BEFORE CHANGING THE PRICE BANDS
B20: - These bands encode an assumed blended rate. Before you trust them, divide a band midpoint by the hours you actually spent on a comparable delivered feature and check the implied rate is one you would defend out loud.
B21: - The XL band tops out at $25,000 by design. A feature that genuinely exceeds it is not a feature - it is a phase. Decompose it.
B22: - Recalibrate these bands from delivered actuals roughly twice a year. The Actuals and Calibration sheet in the companion Deep Estimator workbook is where that evidence accumulates.

Sheet Project Roll-up
A1: PROJECT ROLL-UP
A2: Feature build effort is roughly half of a project. This sheet adds the other half.
A4: 1. FEATURE BUILD SUBTOTAL
B5: Number of features scored | C5: ='Ballpark Estimator'!$H$37 -> 5 | D5: From the Ballpark Estimator sheet.
B6: Sum of feature point estimates | C6: ='Ballpark Estimator'!$J$37 -> 16211.538
A8: 2. PROJECT CONTEXT FACTORS
B9: These apply to the whole project. Enter a level of 1 to 4 for each. Factors combine additively (1 + sum of the deviations), not multiplicatively - multiplying nine factors together produces absurd numbers.
B10: FACTOR | C10: LEVEL (1-4) | D10: MULTI- PLIER | F10: LEVEL DEFINITIONS (1 / 2 / 3 / 4) | H10: Lvl 1 | I10: Lvl 2 | J10: Lvl 3 | K10: Lvl 4
B11: Codebase maturity | C11: 2 | D11: =IFERROR(INDEX($H11:$K11,$C11),1) -> 1.1 | F11: Greenfield / young and clean / mature with history / legacy, low test coverage | H11: 1 | I11: 1.1 | J11: 1.2 | K11: 1.45
B12: Stack & domain familiarity | C12: 1 | D12: =IFERROR(INDEX($H12:$K12,$C12),1) -> 1 | F12: Core stack, done before / adjacent, some learning / new to the team / new to the team | H12: 1 | I12: 1.15 | J12: 1.35 | K12: 1.35
B13: Specification quality at estimate time | C13: 3 | D13: =IFERROR(INDEX($H13:$K13,$C13),1) -> 1.2 | F13: Signed-off AC / clear written brief / outline or slide deck / verbal conversation only | H13: 0.95 | I13: 1 | J13: 1.2 | K13: 1.45
B14: Compliance & data sensitivity | C14: 1 | D14: =IFERROR(INDEX($H14:$K14,$C14),1) -> 1 | F14: None / handles PII / regulated - HIPAA, SOC2, GDPR audit / regulated | H14: 1 | I14: 1.15 | J14: 1.4 | K14: 1.4
B15: Client decision structure | C15: 2 | D15: =IFERROR(INDEX($H15:$K15,$C15),1) -> 1.1 | F15: One fast approver / two or three / committee sign-off / committee plus external review | H15: 1 | I15: 1.1 | J15: 1.25 | K15: 1.4
B16: COMPOSITE CONTEXT MULTIPLIER | D16: =MIN($C17,1+SUM($D$11:$D$15)-COUNT($D$11:$D$15)) -> 1.4 | F16: Applied to the feature subtotal before overheads are calculated.
B17: Cap on composite multiplier | C17: 2.5 | F17: A safety rail. If you are hitting the cap, the project needs a discovery phase, not an estimate.
A19: 3. ADJUSTED BUILD BASE
B20: Feature subtotal x composite context multiplier | C20: =$C$6*$D$16 -> 22696.154 | F20: All percentages below are applied to this figure.
A22: 4. WORK THAT FEATURE SCORING NEVER CAPTURES
B23: COST LINE | C23: % OF BASE | D23: AMOUNT | F23: WHAT IT COVERS
B24: Shared foundation & scaffolding | C24: 0.12 | D24: =$C$20*$C24 -> 2723.5385 | F24: Repo setup, environments, auth scaffolding, design system, base data model, agent context files. Counted once, belongs to no single feature.
B25: Discovery & specification | C25: 0.06 | D25: =$C$20*$C25 -> 1361.7692 | F25: Requirements workshops, writing acceptance criteria, technical design decisions.
B26: UX / UI design | C26: 0.08 | D26: =$C$20*$C26 -> 1815.6923 | F26: Wireframes, visual design, design review cycles. Set to zero if the client supplies finished designs - and say so in the exclusions.
B27: QA & user acceptance testing | C27: 0.08 | D27: =$C$20*$C27 -> 1815.6923 | F27: Test planning, exploratory testing, regression, UAT support and defect triage.
B28: DevOps, environments & release | C28: 0.05 | D28: =$C$20*$C28 -> 1134.8077 | F28: Pipelines, staging, secrets, monitoring, release management.
B29: Documentation & handover | C29: 0.03 | D29: =$C$20*$C29 -> 680.88462 | F29: Technical docs, runbooks, walkthrough sessions.
B30: Project management & client comms | C30: 0.1 | D30: =$C$20*$C30 -> 2269.6154 | F30: Planning, stand-ups, status reporting, demos, change control.
B31: Cross-feature integration | C31: =MIN($C32,$C33*$C$5) -> 0.1 | D31: =$C$20*$C31 -> 2269.6154 | F31: Wiring features to each other, shared-state bugs, end-to-end flows. Grows with feature count because interfaces grow faster than features do.
B32: Integration cap | C32: 0.25
B33: Integration rate per feature | C33: 0.02
B34: TOTAL NON-FEATURE WORK | C34: =SUM($C$24:$C$31) -> 0.62 | D34: =SUM($D$24:$D$31) -> 14071.615
A36: 5. CONTINGENCY
B37: Average Uncertainty score across features | C37: =IFERROR(AVERAGEIF('Ballpark Estimator'!$B$7:$B$36,"?*",'Ballpark Estimator'!$F$7:$F$36),0) -> 2.6
B38: Average Risk score across features | C38: =IFERROR(AVERAGEIF('Ballpark Estimator'!$B$7:$B$36,"?*",'Ballpark Estimator'!$G$7:$G$36),0) -> 2.8
B39: Base contingency | C39: 0.05
B40: Per point of average Uncertainty | C40: 0.02
B41: Per point of average Risk | C41: 0.02
B42: CONTINGENCY RATE | C42: =$C$39+$C$37*$C$40+$C$38*$C$41 -> 0.158 | D42: =($C$20+$D$34)*$C42 -> 5809.3075 | F42: Contingency covers known-unknowns inside the agreed scope. It is not a discount to give away in negotiation.
A44: 6. PROJECT ESTIMATE
B45: Adjusted feature build | C45: =$C$20 -> 22696.154
B46: Non-feature work | C46: =$D$34 -> 14071.615
...
